<?xml version="1.0" ?>
<!-- =================================================================================== -->
<!-- |    This document was autogenerated by xacro from /home/li-jinjie/ros1/jsk_aerial_robot_ws/src/jsk_aerial_robot_dev/robots/gimbalrotor/robots/bi/gimbalrotor.urdf.xacro | -->
<!-- |    EDITING THIS FILE BY HAND IS NOT RECOMMENDED                                 | -->
<!-- =================================================================================== -->
<robot name="gimbalrotor">
  <!-- general attribute -->
  <baselink name="fc"/>
  <thrust_link name="thrust"/>
  <m_f_rate value="-0.0172"/>
  <!-- [N] -->

    ## link
    #### root link (vitrual) ####

  <link name="root">
    <inertial>
      <origin rpy="0 0 0" xyz="0 0 0"/>
      <mass value="0.00001"/>
      <inertia ixx="0.000001" ixy="0.000000" ixz="0.000000" iyy="0.000001" iyz="0.000000" izz="0.000001"/>
    </inertial>
  </link>


    #### base link ####

  <link name="base_link">
    <inertial>
      <origin rpy="0 0 0" xyz="0 0 -0.134417"/>
      <mass value="0.942442"/>
      <inertia ixx="0.015351" ixy="-0.000002" ixz="-0.000024" iyy="0.002766" iyz="0.000002" izz="0.013177"/>
    </inertial>
    <visual>
      <geometry>
        <mesh filename="package://gimbalrotor/urdf/bi/mesh/kxr_flight_unit_base_link.dae" scale="0.001 0.001 0.001"/>
        <origin rpy="0 0 0" xyz="0 0 0"/>
      </geometry>
    </visual>
    <collision>
      <origin rpy="0 0 0" xyz="0 0 0"/>
      <geometry>
        <box size="0.1 0.3 0.21"/>
      </geometry>
    </collision>
  </link>
  <gazebo reference="base_link">
    <dampingFactor>0.00</dampingFactor>
  </gazebo>


    #### rotor coord link (virtual)####

  <link name="rotor_arm1">
    <inertial>
      <origin rpy="0 0 0" xyz="0 0 0"/>
      <mass value="0.00001"/>
      <inertia ixx="0.000001" ixy="0.000000" ixz="0.000000" iyy="0.000001" iyz="0.000000" izz="0.000001"/>
    </inertial>
  </link>
  <link name="rotor_arm2">
    <inertial>
      <origin rpy="0 0 0" xyz="0 0 0"/>
      <mass value="0.00001"/>
      <inertia ixx="0.000001" ixy="0.000000" ixz="0.000000" iyy="0.000001" iyz="0.000000" izz="0.000001"/>
    </inertial>
  </link>


    #### fcu frame ####

  <link name="fc">
    <inertial>
      <origin rpy="0 0 0" xyz="0 0 0"/>
      <mass value="0.00001"/>
      <inertia ixx="0.000001" ixy="0.000000" ixz="0.000000" iyy="0.000001" iyz="0.000000" izz="0.000001"/>
    </inertial>
  </link>


    ## joints ##
    #### fixed frames (virtual) ####

  <joint name="root_joint" type="fixed">
    <parent link="root"/>
    <child link="base_link"/>
    <origin rpy="0 0 0" xyz="0 0 0"/>
    <axis xyz="0 0 1"/>
  </joint>
  <joint name="fc_joint" type="fixed">
    <parent link="base_link"/>
    <child link="fc"/>
    <origin rpy="0 0 0" xyz="0 0 0"/>
    <axis xyz="0 0 1"/>
  </joint>


    #### rotor coord link joint (virtual) ####

  <joint name="rotor_coord_joint1" type="fixed">
    <parent link="base_link"/>
    <child link="rotor_arm1"/>
    <origin rpy="0 0 1.5707963267948966" xyz="0 0.154 0.051"/>
    <axis xyz="0 0 1"/>
  </joint>
  <joint name="rotor_coord_joint2" type="fixed">
    <parent link="base_link"/>
    <child link="rotor_arm2"/>
    <origin rpy="0 0 -1.5707963267948966" xyz="0 -0.154 0.051"/>
    <axis xyz="0 0 1"/>
  </joint>


    #### gimbal link joint ####

  <joint name="gimbal1" type="revolute">
    <limit effort="6.6" lower="-1.57" upper="1.57" velocity="3.0"/>
    <parent link="rotor_arm1"/>
    <child link="gimbal_link1"/>
    <origin rpy="0 0 0" xyz="0 0 0"/>
    <axis xyz="1 0 0"/>
    <dynamics damping="0.8" friction="0.0"/>
  </joint>
  <joint name="gimbal2" type="revolute">
    <limit effort="6.6" lower="-1.57" upper="1.57" velocity="3.0"/>
    <parent link="rotor_arm2"/>
    <child link="gimbal_link2"/>
    <origin rpy="0 0 0" xyz="0 0 0"/>
    <axis xyz="1 0 0"/>
    <dynamics damping="0.8" friction="0.0"/>
  </joint>


    ## hardware interface ##

  <transmission name="joint_tran1">
    <type>transmission_interface/SimpleTransmission</type>
    <joint name="gimbal1">
      <hardwareInterface>hardware_interface/EffortJointInterface</hardwareInterface>
    </joint>
    <actuator name="servo1">
      <hardwareInterface>hardware_interface/EffortJointInterface</hardwareInterface>
      <mechanicalReduction>1</mechanicalReduction>
    </actuator>
  </transmission>
  <transmission name="joint_tran2">
    <type>transmission_interface/SimpleTransmission</type>
    <joint name="gimbal2">
      <hardwareInterface>hardware_interface/EffortJointInterface</hardwareInterface>
    </joint>
    <actuator name="servo2">
      <hardwareInterface>hardware_interface/EffortJointInterface</hardwareInterface>
      <mechanicalReduction>1</mechanicalReduction>
    </actuator>
  </transmission>
  <gazebo reference="linkbase_link">
    <mu1>0.1</mu1>
    <mu2>0.1</mu2>
  </gazebo>

    ## link
    #### rotor link  ####

  <link name="gimbal_link1">
    <inertial>
      <origin rpy="0 0 0" xyz="0.0835 0 0"/>
      <mass value="0.250950"/>
      <inertia ixx="0.001920" ixy="0.000002" ixz="-0.000024" iyy="0.000249" iyz="0.000002" izz="0.013177"/>
    </inertial>
    <visual>
      <origin rpy="0 0 -1.5707963267948966" xyz="0 0 0"/>
      <geometry>
        <mesh filename="package://gimbalrotor/urdf/bi/mesh/thrust_link_left_straight.dae" scale="0.001 0.001 0.001"/>
      </geometry>
    </visual>
    <collision>
      <origin rpy="0 0 0" xyz="0.0835 0 0"/>
      <geometry>
        <cylinder length="0.1" radius="0.1"/>
      </geometry>
    </collision>
  </link>
  <gazebo reference="gimbal_link1">
    <dampingFactor>0.00</dampingFactor>
  </gazebo>


    #### rotor parent link (virtual) ####

  <link name="rotor_parent1">
    <inertial>
      <origin rpy="0 0 0" xyz="0 0 0"/>
      <mass value="0.00001"/>
      <inertia ixx="0.000001" ixy="0.000000" ixz="0.000000" iyy="0.000001" iyz="0.000000" izz="0.000001"/>
    </inertial>
  </link>


    #### thrust link (virtual) ####

  <link name="thrust1">
    <inertial>
      <origin rpy="0 0 0" xyz="0 0 0"/>
      <mass value="0.00001"/>
      <inertia ixx="0.000001" ixy="0.000000" ixz="0.000000" iyy="0.000001" iyz="0.000000" izz="0.000001"/>
    </inertial>
  </link>
  <gazebo reference="thrust1">
    <dampingFactor>0.00</dampingFactor>
  </gazebo>


    ## joints ##
    #### rotor parent link joint (virtual) ####

  <joint name="rotor_parent_link_joint1" type="fixed">
    <parent link="gimbal_link1"/>
    <child link="rotor_parent1"/>
    <origin rpy="0 0 0" xyz="0.0835 0 0"/>
    <axis xyz="0 0 1"/>
  </joint>


    #### rotor joint (virtual) ####

  <joint name="rotor1" type="continuous">
    <limit effort="100.0" lower="1.0" upper="18.0" velocity="0.5"/>
    <parent link="rotor_parent1"/>
    <child link="thrust1"/>
    <origin rpy="0 0 0" xyz="0 0 0"/>
    <axis xyz="0 0 1"/>
  </joint>


    #### hardware interface ####

  <transmission name="rotor_tran1">
    <type>transmission_interface/SimpleTransmission</type>
    <joint name="rotor1">
      <hardwareInterface>RotorInterface</hardwareInterface>
    </joint>
    <actuator name="rotor_actuator1">
      <hardwareInterface>RotorInterface</hardwareInterface>
      <mechanicalReduction>1</mechanicalReduction>
    </actuator>
  </transmission>

    ## link
    #### rotor link  ####

  <link name="gimbal_link2">
    <inertial>
      <origin rpy="0 0 0" xyz="0.0835 0 0"/>
      <mass value="0.250950"/>
      <inertia ixx="0.001920" ixy="0.000002" ixz="-0.000024" iyy="0.000249" iyz="0.000002" izz="0.013177"/>
    </inertial>
    <visual>
      <origin rpy="0 0 -1.5707963267948966" xyz="0 0 0"/>
      <geometry>
        <mesh filename="package://gimbalrotor/urdf/bi/mesh/thrust_link_left_straight.dae" scale="0.001 0.001 0.001"/>
      </geometry>
    </visual>
    <collision>
      <origin rpy="0 0 0" xyz="0.0835 0 0"/>
      <geometry>
        <cylinder length="0.1" radius="0.1"/>
      </geometry>
    </collision>
  </link>
  <gazebo reference="gimbal_link2">
    <dampingFactor>0.00</dampingFactor>
  </gazebo>


    #### rotor parent link (virtual) ####

  <link name="rotor_parent2">
    <inertial>
      <origin rpy="0 0 0" xyz="0 0 0"/>
      <mass value="0.00001"/>
      <inertia ixx="0.000001" ixy="0.000000" ixz="0.000000" iyy="0.000001" iyz="0.000000" izz="0.000001"/>
    </inertial>
  </link>


    #### thrust link (virtual) ####

  <link name="thrust2">
    <inertial>
      <origin rpy="0 0 0" xyz="0 0 0"/>
      <mass value="0.00001"/>
      <inertia ixx="0.000001" ixy="0.000000" ixz="0.000000" iyy="0.000001" iyz="0.000000" izz="0.000001"/>
    </inertial>
  </link>
  <gazebo reference="thrust2">
    <dampingFactor>0.00</dampingFactor>
  </gazebo>


    ## joints ##
    #### rotor parent link joint (virtual) ####

  <joint name="rotor_parent_link_joint2" type="fixed">
    <parent link="gimbal_link2"/>
    <child link="rotor_parent2"/>
    <origin rpy="0 0 0" xyz="0.0835 0 0"/>
    <axis xyz="0 0 1"/>
  </joint>


    #### rotor joint (virtual) ####

  <joint name="rotor2" type="continuous">
    <limit effort="100.0" lower="1.0" upper="18.0" velocity="0.5"/>
    <parent link="rotor_parent2"/>
    <child link="thrust2"/>
    <origin rpy="0 0 0" xyz="0 0 0"/>
    <axis xyz="0 0 -1"/>
  </joint>


    #### hardware interface ####

  <transmission name="rotor_tran2">
    <type>transmission_interface/SimpleTransmission</type>
    <joint name="rotor2">
      <hardwareInterface>RotorInterface</hardwareInterface>
    </joint>
    <actuator name="rotor_actuator2">
      <hardwareInterface>RotorInterface</hardwareInterface>
      <mechanicalReduction>1</mechanicalReduction>
    </actuator>
  </transmission>
</robot>
